exception:
  unknown_error: "&cНеизвестная ошибка!"
result:
  success: "&aУспех!"
util:
